<?xml version="1.0"?>
<robot name="balance">

  <material name="body">
    <color rgba="0.5 0.5 0.5 1"/>
  </material>

  <material name="wheel">
    <color rgba="0.2 0.2 0.2 1"/>
  </material>

  <link name="torso">
    <visual>
      <geometry>
        <box size="0.1 0.037 0.171"/>
      </geometry>
      <!-- 0.034 - 0.020 + 0.171/2 -->
      <origin rpy="0 0 0" xyz="0 0.0 0.0995"/>
      <material name="body"/>
    </visual>
    <collision>
      <geometry>
        <box size="0.1 0.037 0.171"/>
      </geometry>
      <origin rpy="0 0 0" xyz="0 0.0 0.0995"/>
    </collision>
    <inertial>
      <!-- Total mass is 0.578kg, wheels weigh 0.032kg each -->
      <mass value="0.514"/>
      <!-- Assume flat plate mass moment of inertia calcs with above mass and dimensions -->
      <inertia ixx="0.0012568" ixy="0.0" ixz="0.0" iyy="0.001311" iyz="0.0" izz="0.000487"/>
      <!-- <origin rpy="0 0 0" xyz="0 0.0 0.1285"/> -->

      <origin rpy="0 0 0" xyz="0 0.0 0.057"/>
    </inertial>
  </link>

  <link name="l_wheel">
    <visual>
      <geometry>
        <cylinder length="0.026" radius="0.034"/>
      </geometry>
      <origin rpy="0 1.5707963 0" xyz="0 0 0"/>
      <material name="wheel"/>
    </visual>
    <collision>
      <geometry>
        <cylinder length="0.026" radius="0.034"/>
      </geometry>
      <origin rpy="0 1.5707963 0" xyz="0 0 0"/>
      <contact_coefficients mu="0.8" />
    </collision>
    <inertial>
      <mass value="0.032"/>
      <inertia ixx="1.3E-05" ixy="0.0" ixz="0.0" iyy="1.3E-05" iyz="0.0" izz="2.3E-05"/>
      <origin rpy="0 0 0" xyz="0 0 0"/>
    </inertial>
  </link>

  <link name="r_wheel">
    <visual>
      <geometry>
        <cylinder length="0.026" radius="0.034"/>
      </geometry>
      <origin rpy="0 1.5707963 0" xyz="0 0 0"/>
      <material name="wheel"/>
    </visual>
    <collision>
      <geometry>
        <cylinder length="0.026" radius="0.034"/>
      </geometry>
      <origin rpy="0 1.5707963 0" xyz="0 0 0"/>
      <contact_coefficients mu="0.8" />
    </collision>
    <inertial>
      <mass value="0.032"/>
      <inertia ixx="1.3E-05" ixy="0.0" ixz="0.0" iyy="1.3E-05" iyz="0.0" izz="2.3E-05"/>
      <origin rpy="0 0 0" xyz="0 0 0"/>
    </inertial>
  </link>

  <joint name="torso_l_wheel" type="continuous">
    <parent link="torso"/>
    <child link="l_wheel"/>
    <axis xyz="-1 0 0"/>
    <limit effort="5.0" lower="0.0" upper="0.548" velocity="0.0"/>
    <origin rpy="0 0 0" xyz="-0.074 0.0 0.034"/>
  </joint>

  <joint name="torso_r_wheel" type="continuous">
    <parent link="torso"/>
    <child link="r_wheel"/>
    <axis xyz="1 0 0"/>
   <limit effort="5.0" lower="0.0" upper="0.548" velocity="0.0"/>
   <origin rpy="0 0 0" xyz="0.074 0.0 0.034"/>
  </joint>

</robot>
